Workbook

Sheet Gannt_11052025_11182025
A3: Data
A4: Work item | B4: Name | C4: Estimated Work | D4: Remaining Work
A5: {=_xlfn._xlws.FILTER(VSTS_3e70086c_f553_49d1_81be_7ca3114b6431[ID], (VSTS_3e70086c_f553_49d1_81be_7ca3114b6431[Work Item Type]="Product Backlog Item")+(VSTS_3e70086c_f553_49d1_81be_7ca3114b6431[Work Item Type]="Bug"))} -> 24239 | B5: =_xlfn.XLOOKUP($A5, VSTS_3e70086c_f553_49d1_81be_7ca3114b6431[ID], VSTS_3e70086c_f553_49d1_81be_7ca3114b6431[Title]) -> Branding: Variablize font color for categories in option pricing | C5: =SUMIF(VSTS_3e70086c_f553_49d1_81be_7ca3114b6431[Parent],Gannt_11052025_11182025!$A5,VSTS_3e70086c_f553_49d1_81be_7ca3114b6431[Original Estimate]) -> 31 | D5: =SUMIF(VSTS_3e70086c_f553_49d1_81be_7ca3114b6431[Parent],Gannt_11052025_11182025!$A5,VSTS_3e70086c_f553_49d1_81be_7ca3114b6431[Remaining Work]) -> 1
A6: 28596 | B6: =_xlfn.XLOOKUP($A6, VSTS_3e70086c_f553_49d1_81be_7ca3114b6431[ID], VSTS_3e70086c_f553_49d1_81be_7ca3114b6431[Title]) -> Design Selections: Image disparity | C6: =SUMIF(VSTS_3e70086c_f553_49d1_81be_7ca3114b6431[Parent],Gannt_11052025_11182025!$A6,VSTS_3e70086c_f553_49d1_81be_7ca3114b6431[Original Estimate]) -> 28 | D6: =SUMIF(VSTS_3e70086c_f553_49d1_81be_7ca3114b6431[Parent],Gannt_11052025_11182025!$A6,VSTS_3e70086c_f553_49d1_81be_7ca3114b6431[Remaining Work]) -> 18
A7: 28613 | B7: =_xlfn.XLOOKUP($A7, VSTS_3e70086c_f553_49d1_81be_7ca3114b6431[ID], VSTS_3e70086c_f553_49d1_81be_7ca3114b6431[Title]) -> Auth: Migrate Spike code to development branch | C7: =SUMIF(VSTS_3e70086c_f553_49d1_81be_7ca3114b6431[Parent],Gannt_11052025_11182025!$A7,VSTS_3e70086c_f553_49d1_81be_7ca3114b6431[Original Estimate]) -> 48.5 | D7: =SUMIF(VSTS_3e70086c_f553_49d1_81be_7ca3114b6431[Parent],Gannt_11052025_11182025!$A7,VSTS_3e70086c_f553_49d1_81be_7ca3114b6431[Remaining Work]) -> 0
A8: 28614 | B8: =_xlfn.XLOOKUP($A8, VSTS_3e70086c_f553_49d1_81be_7ca3114b6431[ID], VSTS_3e70086c_f553_49d1_81be_7ca3114b6431[Title]) -> Auth: Implement domain match policy | C8: =SUMIF(VSTS_3e70086c_f553_49d1_81be_7ca3114b6431[Parent],Gannt_11052025_11182025!$A8,VSTS_3e70086c_f553_49d1_81be_7ca3114b6431[Original Estimate]) -> 43 | D8: =SUMIF(VSTS_3e70086c_f553_49d1_81be_7ca3114b6431[Parent],Gannt_11052025_11182025!$A8,VSTS_3e70086c_f553_49d1_81be_7ca3114b6431[Remaining Work]) -> 5
A9: 28615 | B9: =_xlfn.XLOOKUP($A9, VSTS_3e70086c_f553_49d1_81be_7ca3114b6431[ID], VSTS_3e70086c_f553_49d1_81be_7ca3114b6431[Title]) -> Auth: Okta user can authenticate to VDS | C9: =SUMIF(VSTS_3e70086c_f553_49d1_81be_7ca3114b6431[Parent],Gannt_11052025_11182025!$A9,VSTS_3e70086c_f553_49d1_81be_7ca3114b6431[Original Estimate]) -> 24 | D9: =SUMIF(VSTS_3e70086c_f553_49d1_81be_7ca3114b6431[Parent],Gannt_11052025_11182025!$A9,VSTS_3e70086c_f553_49d1_81be_7ca3114b6431[Remaining Work]) -> 24
A10: 28616 | B10: =_xlfn.XLOOKUP($A10, VSTS_3e70086c_f553_49d1_81be_7ca3114b6431[ID], VSTS_3e70086c_f553_49d1_81be_7ca3114b6431[Title]) -> Auth: display "user not provisioned" error message | C10: =SUMIF(VSTS_3e70086c_f553_49d1_81be_7ca3114b6431[Parent],Gannt_11052025_11182025!$A10,VSTS_3e70086c_f553_49d1_81be_7ca3114b6431[Original Estimate]) -> 18 | D10: =SUMIF(VSTS_3e70086c_f553_49d1_81be_7ca3114b6431[Parent],Gannt_11052025_11182025!$A10,VSTS_3e70086c_f553_49d1_81be_7ca3114b6431[Remaining Work]) -> 2
A11: 28645 | B11: =_xlfn.XLOOKUP($A11, VSTS_3e70086c_f553_49d1_81be_7ca3114b6431[ID], VSTS_3e70086c_f553_49d1_81be_7ca3114b6431[Title]) -> Interfacelift Training "3rd Party Authorization 2" | C11: =SUMIF(VSTS_3e70086c_f553_49d1_81be_7ca3114b6431[Parent],Gannt_11052025_11182025!$A11,VSTS_3e70086c_f553_49d1_81be_7ca3114b6431[Original Estimate]) -> 45 | D11: =SUMIF(VSTS_3e70086c_f553_49d1_81be_7ca3114b6431[Parent],Gannt_11052025_11182025!$A11,VSTS_3e70086c_f553_49d1_81be_7ca3114b6431[Remaining Work]) -> 43.5
A12: 28652 | B12: =_xlfn.XLOOKUP($A12, VSTS_3e70086c_f553_49d1_81be_7ca3114b6431[ID], VSTS_3e70086c_f553_49d1_81be_7ca3114b6431[Title]) -> RC for 11/10 | C12: =SUMIF(VSTS_3e70086c_f553_49d1_81be_7ca3114b6431[Parent],Gannt_11052025_11182025!$A12,VSTS_3e70086c_f553_49d1_81be_7ca3114b6431[Original Estimate]) -> 0 | D12: =SUMIF(VSTS_3e70086c_f553_49d1_81be_7ca3114b6431[Parent],Gannt_11052025_11182025!$A12,VSTS_3e70086c_f553_49d1_81be_7ca3114b6431[Remaining Work]) -> 0
A13: 28653 | B13: =_xlfn.XLOOKUP($A13, VSTS_3e70086c_f553_49d1_81be_7ca3114b6431[ID], VSTS_3e70086c_f553_49d1_81be_7ca3114b6431[Title]) -> Regression Test: Today's Appts | C13: =SUMIF(VSTS_3e70086c_f553_49d1_81be_7ca3114b6431[Parent],Gannt_11052025_11182025!$A13,VSTS_3e70086c_f553_49d1_81be_7ca3114b6431[Original Estimate]) -> 0 | D13: =SUMIF(VSTS_3e70086c_f553_49d1_81be_7ca3114b6431[Parent],Gannt_11052025_11182025!$A13,VSTS_3e70086c_f553_49d1_81be_7ca3114b6431[Remaining Work]) -> 3

Sheet DirectQuery_11052025_11182025
A1: Project: VeoDesignStudio Server: dev.azure.com/buildontechnologies Query: CurrentIterationTaskCapacity List type: Flat
A2: ID | B2: Work Item Type | C2: Title | D2: Tags | E2: Remaining Work | F2: Original Estimate | G2: Activity | H2: Parent
A3: 24239 | B3: Product Backlog Item | C3: Branding: Variablize font color for categories in option pricing | D3: branding
A4: 28596 | B4: Bug | C4: Design Selections: Image disparity
A5: 28613 | B5: Product Backlog Item | C5: Auth: Migrate Spike code to development branch | D5: Auth; scripts | H5: 28426
A6: 28614 | B6: Product Backlog Item | C6: Auth: Implement domain match policy | D6: Auth | H6: 28426
A7: 28615 | B7: Product Backlog Item | C7: Auth: Okta user can authenticate to VDS | D7: Auth | H7: 28426
A8: 28616 | B8: Product Backlog Item | C8: Auth: display "user not provisioned" error message | D8: Auth | H8: 28426
A9: 28645 | B9: Product Backlog Item | C9: Interfacelift Training "3rd Party Authorization 2" | D9: No QA
A10: 28646 | B10: Task | C10: Justin Training | E10: 15 | F10: 15 | G10: Development | H10: 28645
A11: 28647 | B11: Task | C11: Daniel Training | E11: 15 | F11: 15 | G11: Development | H11: 28645
A12: 28648 | B12: Task | C12: Reid Training | E12: 13.5 | F12: 15 | G12: Development | H12: 28645
A13: 28651 | B13: Task | C13: Write Test Cases | E13: 3 | G13: Test Design | H13: 28653
A14: 28652 | B14: Product Backlog Item | C14: RC for 11/10
A15: 28653 | B15: Product Backlog Item | C15: Regression Test: Today's Appts | D15: QA only | H15: 21389
A16: 28654 | B16: Task | C16: Create and deploy RC | G16: Development | H16: 28652
A17: 28655 | B17: Task | C17: Test RC in Staging | G17: Testing | H17: 28652
A18: 28656 | B18: Task | C18: Run e2e automated test in Staging | G18: Testing | H18: 28652
A19: 28657 | B19: Task | C19: Deployment Planning Meeting | H19: 28652
A20: 28658 | B20: Task | C20: Write QA Tests | F20: 3 | G20: Test Design | H20: 28613
A21: 28659 | B21: Task | C21: Execute QA Tests | F21: 4 | G21: Testing | H21: 28613
A22: 28660 | B22: Task | C22: PO Review | F22: 1 | H22: 28613
A23: 28661 | B23: Task | C23: Write QA Tests | F23: 3 | G23: Test Design | H23: 28614
A24: 28662 | B24: Task | C24: Execute QA Tests | E24: 4 | F24: 4 | G24: Testing | H24: 28614
A25: 28663 | B25: Task | C25: PO Review | E25: 1 | F25: 1 | H25: 28614
A26: 28664 | B26: Task | C26: Write QA Tests | E26: 3 | F26: 3 | G26: Test Design | H26: 28615
A27: 28665 | B27: Task | C27: Execute QA Tests | E27: 4 | F27: 4 | G27: Testing | H27: 28615
A28: 28666 | B28: Task | C28: PO Review | E28: 1 | F28: 1 | H28: 28615
A29: 28667 | B29: Task | C29: Entity creation | F29: 2 | G29: Development | H29: 28613
A30: 28668 | B30: Task | C30: Write QA Tests | F30: 2 | G30: Test Design | H30: 28616
A31: 28669 | B31: Task | C31: Execute QA Tests | E31: 1 | F31: 1 | G31: Testing | H31: 28616
A32: 28670 | B32: Task | C32: Run migration | F32: 2 | G32: Development | H32: 28613
A33: 28671 | B33: Task | C33: PO Review | E33: 1 | F33: 1 | H33: 28616
A34: 28672 | B34: Task | C34: Confirmation Testing | E34: 3 | F34: 3 | G34: Testing | H34: 28596
A35: 28673 | B35: Task | C35: Update GetAuthProviders use case | F35: 4 | G35: Development | H35: 28613
A36: 28674 | B36: Task | C36: PO Review | E36: 1 | F36: 1 | H36: 28596
A37: 28675 | B37: Task | C37: Write QA Tests | F37: 2 | G37: Test Design | H37: 24239
A38: 28676 | B38: Task | C38: PO Review | E38: 1 | F38: 1 | H38: 24239
A39: 28677 | B39: Task | C39: Execute QA Tests | F39: 3 | G39: Testing | H39: 24239
A40: 28679 | B40: Task | C40: Validate JWTs | F40: 4 | G40: Development | H40: 28613
...

Sheet Sheet2

Sheet VSTS_ValidationWS_1
A1: value doesn't matter | B1: value doesn't matter | C1: value doesn't matter | D1: value doesn't matter | E1: \ | F1: Deployment | G1: \ | H1: Deployment | I1: Bug | J1: Deployment
A2: readOnlyTestRange_@ | B2: readOnlyTestRange_0 | C2: readOnlyTestRange_M/d/yyyy h:mm AM/PM | D2: readOnlyTestRange_General | E2: \Defects | F2: Design | G2: \Active | H2: Design | I2: Epic | J2: Design
E3: \Integration | F3: Development | G3: \Active\Product Backlog | H3: Development | I3: Feature | J3: Development
E4: \Product Team | F4: Documentation | G4: \Active\Product Backlog\3rd Party Authorization 1 | H4: Documentation | I4: Impediment | J4: Documentation
E5: \Product Team\Story Time | F5: Requirements | G5: \Active\Product Backlog\3rd Party Authorization 2 | H5: Requirements | I5: Initiative | J5: Requirements
E6: \Requests | F6: Testing | G6: \Active\Product Backlog\Assigned Communities 1 | H6: Test Design | I6: Product Backlog Item | J6: Testing
E7: all_VSTS_3e70086c_f553_49d1_81be_7ca3114b6431_System.AreaPath | F7: all_VSTS_3e70086c_f553_49d1_81be_7ca3114b6431_Bug_Microsoft.VSTS.Common.Activity | G7: \Active\Product Backlog\Assigned Communities 2 | H7: Testing | I7: Task | J7: Test Design
G8: \Active\Product Backlog\Branding - Flintrock | H8: all_VSTS_3e70086c_f553_49d1_81be_7ca3114b6431_Task_Microsoft.VSTS.Common.Activity | I8: Test Case | J8: all_VSTS_3e70086c_f553_49d1_81be_7ca3114b6431_Microsoft.VSTS.Common.Activity
G9: \Active\Product Backlog\Branding Theme Editor 1 | I9: all_VSTS_3e70086c_f553_49d1_81be_7ca3114b6431_System.WorkItemType
G10: \Active\Product Backlog\Branding Theme Editor 2
G11: \Active\Product Backlog\Branding Theme Editor 4
G12: \Active\Product Backlog\Branding Theme Editor 5
G13: \Active\Product Backlog\Branding Theme Editor 6
G14: \Active\Product Backlog\Branding Theme Editor 7
G15: \Active\Product Backlog\Branding Theme Version 3
G16: \Active\Product Backlog\Builder Branding - Foundation 1
G17: \Active\Product Backlog\Builder Branding - Foundation 2
G18: \Active\Product Backlog\Builder Branding 3
G19: \Active\Product Backlog\Builder Branding 4
G20: \Active\Product Backlog\Builder Option Codes 1
G21: \Active\Product Backlog\Builder Option Codes 2
... G145: all_VSTS_3e70086c_f553_49d1_81be_7ca3114b6431_System.IterationPath
